Workbook

Sheet Cari Data
A2: =CONCATENATE("*",E2,"*") -> *MUCSPA63640PSIND* | C2: Masukan PPID Lengkap / Kode PPID | D2: : | E2: MUCSPA63640PSIND
D5: :
C6: =IF(E2="","",IF(E7="","Belum terdaftar sebagai AgenPos",""))
C7: Nopend/Kode Dirian | D7: : | E7: =IF(E2="","",IFERROR(VLOOKUP(A2,'Agen CUM'!$P:$CJ,20,FALSE),"")) -> 16412SC
C8: IdLoc | D8: : | E8: =IF(E2="","",IFERROR(VLOOKUP(A2,'Agen CUM'!$P:$CJ,21,FALSE),"")) -> 6a97bdccd1fe1f64120dcc26
C9: User | D9: : | E9: =IF(E2="","",IFERROR(VLOOKUP(A2,'Agen CUM'!$P:$CJ,22,FALSE),"")) -> info@jte.co.id
C10: Pass | D10: : | E10: =IF(E2="","",IFERROR(VLOOKUP(A2,'Agen CUM'!$P:$CJ,23,FALSE),"")) -> #Muc16412SC$
C11: Nama Agenpos | D11: : | E11: =IF(E2="","",IFERROR(VLOOKUP(A2,'Agen CUM'!$P:$CJ,3,FALSE),"")) -> MUC JTE
C12: Alamat Agenpos | D12: : | E12: =IF(E2="","",IFERROR(VLOOKUP(A2,'Agen CUM'!$P:$CJ,6,FALSE),"")) -> Jl. Raden Saleh No.6B, Sukmajaya, Kec. Sukmajaya, Kota Depok, Jawa Barat 16411
C13: Kelurahan | D13: : | E13: =IF(E2="","",IFERROR(VLOOKUP(A2,'Agen CUM'!$P:$CJ,8,FALSE),"")) -> Sukmajaya
C14: Kecamatan | D14: : | E14: =IF(E2="","",IFERROR(VLOOKUP(A2,'Agen CUM'!$P:$CJ,9,FALSE),"")) -> Sukmajaya
C15: Kota/Kab | D15: : | E15: =IF(E2="","",IFERROR(VLOOKUP(A2,'Agen CUM'!$P:$CJ,10,FALSE),"")) -> Depok
C16: Nama Pemilik/Pengelola | D16: : | E16: =IF(E2="","",IFERROR(VLOOKUP(A2,'Agen CUM'!$P:$CJ,4,FALSE),"")) -> ARIYANTO
C17: No Handphone | D17: : | E17: =IF(E2="","",IFERROR(VLOOKUP(A2,'Agen CUM'!$P:$CJ,17,FALSE),"")) -> 08111814351
C18: Email | D18: : | E18: =IF(E2="","",IFERROR(VLOOKUP(A2,'Agen CUM'!$P:$CJ,19,FALSE),"")) -> info@jte.co.id
C19: NIK | D19: : | E19: =IF(E2="","",IFERROR(VLOOKUP(A2,'Agen CUM'!$P:$CJ,13,FALSE),"")) -> 3171031808800013
C20: NPWP | D20: : | E20: =IF(E2="","",IFERROR(VLOOKUP(A2,'Agen CUM'!$P:$CJ,14,FALSE),"")) -> 44.509.760.3-027.000

Sheet Agen CUM
A1: NO | B1: =COUNT(B4:B1049089) -> 0 | C1: =COUNT(C4:#REF!) -> 0 | D1: =COUNT(D4:#REF!) -> 1081 | F1: =COUNT(F4:F1049089) -> 0 | G1: =COUNT(G4:#REF!) -> 819 | I1: =COUNT(I4:I1049089) -> 0 | J1: =COUNT(J4:#REF!) -> 0 | P1: 1 | Q1: 2 | R1: =Q1+1 -> 3 | S1: =R1+1 -> 4 | T1: =S1+1 -> 5 | U1: =T1+1 -> 6 | V1: =U1+1 -> 7 | W1: =V1+1 -> 8 | X1: =W1+1 -> 9 | Y1: =X1+1 -> 10 | ... AP1: =AO1+1 -> 27 | AT1: =AP1+1 -> 28 | AU1: =AT1+1 -> 29 | AV1: =AU1+1 -> 30 | AW1: =AV1+1 -> 31 | AX1: =AW1+1 -> 32 | AY1: =AX1+1 -> 33 | AZ1: =AY1+1 -> 34 | BA1: =AZ1+1 -> 35 | BB1: =BA1+1 -> 36 | ... CD1: =CC1+1 -> 64
B2: STATUS | M2: KURLOG | P2: PPID | Q2: NAMA LOKET DI ONPAYS | R2: NAMA LOKET DI KURLOG | S2: NAMA PEMILIK | U2: ALAMAT LENGKAP | AB2: NO KTP | AC2: NO NPWP | AD2: ELECTRIC AREA | AE2: REKOMENDASI | AF2: NO HP PEMILIK | AG2: NO.HP LOKET | AH2: EMAIL | AI2: NO DIRIAN | AJ2: LOCATION ID | AK2: USER MILE | AL2: PASSWORD MILE | AM2: REGIONAL | AN2: KCU/KC | AO2: NIB ( NO INDUK BERUSAHA) | AP2: NO KBLI | AQ2: NOMOR REKENING | AR2: Nama Bank | AS2: Nama Pemilik | AT2: LATITUDE | AU2: LONGITUDE | AV2: KELENGKAPAN ADMIN | AZ2: PKS | BF2: PERANGKAT | BK2: DATA PENGGANTI KARENA MASALAH NIB | BX2: JENIS USAHA AGEN
B3: SYARAT | C3: PENGAJUAN SURVEY KE POS | D3: PENGAJUAN POS | E3: PENDAFTARAN KURLOG | F3: KELENGKAPAN PERANGKAT | G3: AKTIVASI KURLOG | H3: AKTIVASI SICEPAT | I3: TRAINING | J3: TRANSAKSI | K3: CATATAN | L3: waktu | M3: POS + PPOB | N3: POS ONLY | O3: SICEPAT | T3: ALAMAT PEMIILIK KTP | U3: ALAMAT LENGKAP LOKET | V3: RT/RW | W3: KEL/DESA | X3: KEC | Y3: KAB/KOT | Z3: PROPINSI | AA3: KODE POS | AV3: FORMULIR | AW3: FORM AJUAN POS | AX3: BELUM DIKIRIM | AY3: SUDAH DIKIRIM BELUM KEMBALI | AZ3: SUDAH DIKIRIM SUDAH KEMBALI | BA3: KTP | BB3: NPWP | BC3: NIB | BD3: KBLI | BE3: FOTO TAMPAK DEPAN LOKET | BF3: KOMPUTER/LAPTOP | BG3: HP ANDROID | BH3: PRINTER STICKER | BI3: TIMBANGAN DIGITAL | BJ3: KERTAS STICKER | BK3: ATK DARI POS | BL3: POLA DANA | BM3: NAMA | BN3: ALAMAT | BO3: NO KTP | BP3: TANGGAL LAHIR | BQ3: NPWP | BR3: TELP | BS3: EMAIL | BT3: STATUS | BX3: KATEGORI | BY3: POS | BZ3: SPX | CA3: Lion Parcel | CB3: wahana | CC3: JNT CARGO | CD3: JNT EXPRESS | CE3: SICEPAT | CF3: JNE | CG3: TIKI | CH3: SAP | CI3: ID EXPRESS | CJ3: ANTERAJA | CL3: LEX ID
A4: =IFERROR(__xludf.DUMMYFUNCTION("QUERY(IMPORTRANGE(""https://docs.google.com/spreadsheets/d/1_5pr7i179ukUeMStgLt8tDyJl04piFhnAUYWtrScCDU/edit?pli=1&gid=1386834576#gid=1386834576"", ""'DATLENG'!A4:CK""), ""SELECT * WHERE Col1 IS NOT NULL"", 0)"),1.0) -> 1 | B4: =IFERROR(__xludf.DUMMYFUNCTION("""COMPUTED_VALUE"""),"11 Januari 2022") -> 11 Januari 2022 | C4: =IFERROR(__xludf.DUMMYFUNCTION("""COMPUTED_VALUE"""),"11 Januari 2022") -> 11 Januari 2022 | F4: =IFERROR(__xludf.DUMMYFUNCTION("""COMPUTED_VALUE"""),"3 OKTOBER 2022") -> 3 OKTOBER 2022 | G4: =IFERROR(__xludf.DUMMYFUNCTION("""COMPUTED_VALUE"""),44837.0) -> 44837 | I4: =IFERROR(__xludf.DUMMYFUNCTION("""COMPUTED_VALUE"""),"3/10/2022") -> 3/10/2022 | J4: =IFERROR(__xludf.DUMMYFUNCTION("""COMPUTED_VALUE"""),"3/10/2022") -> 3/10/2022 | P4: =IFERROR(__xludf.DUMMYFUNCTION("""COMPUTED_VALUE"""),"53BSPA29321JBNDS") -> 53BSPA29321JBNDS | Q4: =IFERROR(__xludf.DUMMYFUNCTION("""COMPUTED_VALUE"""),"ALBI") -> ALBI | R4: =IFERROR(__xludf.DUMMYFUNCTION("""COMPUTED_VALUE"""),"IND EXPRESS") -> IND EXPRESS | S4: =IFERROR(__xludf.DUMMYFUNCTION("""COMPUTED_VALUE"""),"Ucup Taojiri") -> Ucup Taojiri | T4: =IFERROR(__xludf.DUMMYFUNCTION("""COMPUTED_VALUE"""),"Panyalahan Rt03 Rw04 Ds. Sinargalih Kec. Lemahsugih Kab Majelangka Jawa Barat") -> Panyalahan Rt03 Rw04 Ds. Sinargalih Kec. Lemahsugih Kab Majelangka Jawa Barat | U4: =IFERROR(__xludf.DUMMYFUNCTION("""COMPUTED_VALUE"""),"Jl Raya Siliwangi No 119 Bantarujeg Blok Cigedang RT 01 RW 07 Kab Majalengka Jawa Barat 45464") -> Jl Raya Siliwangi No 119 Bantarujeg Blok Cigedang RT 01 RW 07 Kab Majalengka Jawa Barat 45464 | V4: =IFERROR(__xludf.DUMMYFUNCTION("""COMPUTED_VALUE"""),"RT01 RW 07") -> RT01 RW 07 | W4: =IFERROR(__xludf.DUMMYFUNCTION("""COMPUTED_VALUE"""),"SINARGALIH") -> SINARGALIH | X4: =IFERROR(__xludf.DUMMYFUNCTION("""COMPUTED_VALUE"""),"Lemahsugih") -> Lemahsugih | Y4: =IFERROR(__xludf.DUMMYFUNCTION("""COMPUTED_VALUE"""),"Majalengka") -> Majalengka | Z4: =IFERROR(__xludf.DUMMYFUNCTION("""COMPUTED_VALUE"""),"JAWA BARAT") -> JAWA BARAT | AA4: =IFERROR(__xludf.DUMMYFUNCTION("""COMPUTED_VALUE"""),"45464") -> 45464 | AB4: =IFERROR(__xludf.DUMMYFUNCTION("""COMPUTED_VALUE"""),"3210010804830141") -> 3210010804830141 | AC4: =IFERROR(__xludf.DUMMYFUNCTION("""COMPUTED_VALUE"""),"93.567.420.0-438.000") -> 93.567.420.0-438.000 | AD4: =IFERROR(__xludf.DUMMYFUNCTION("""COMPUTED_VALUE"""),"CUM - NDS") -> CUM - NDS | AE4: =IFERROR(__xludf.DUMMYFUNCTION("""COMPUTED_VALUE"""),"SUB NURUL DIMAS") -> SUB NURUL DIMAS | AF4: =IFERROR(__xludf.DUMMYFUNCTION("""COMPUTED_VALUE"""),"081313061606") -> 081313061606 | AG4: =IFERROR(__xludf.DUMMYFUNCTION("""COMPUTED_VALUE"""),"081313061606") -> 081313061606 | AH4: =IFERROR(__xludf.DUMMYFUNCTION("""COMPUTED_VALUE"""),"yusuftaojiri83@gmail.com") -> yusuftaojiri83@gmail.com | AI4: =IFERROR(__xludf.DUMMYFUNCTION("""COMPUTED_VALUE"""),"45465S1") -> 45465S1 | AJ4: =IFERROR(__xludf.DUMMYFUNCTION("""COMPUTED_VALUE"""),"6211a4edde67be2ec0415b34") -> 6211a4edde67be2ec0415b34 | AK4: =IFERROR(__xludf.DUMMYFUNCTION("""COMPUTED_VALUE"""),"dm45465s1") -> dm45465s1 | AL4: =IFERROR(__xludf.DUMMYFUNCTION("""COMPUTED_VALUE"""),"password") -> password | AM4: =IFERROR(__xludf.DUMMYFUNCTION("""COMPUTED_VALUE"""),"KANTOR REGIONAL III BANDUNG 40004") -> KANTOR REGIONAL III BANDUNG 40004 | AN4: =IFERROR(__xludf.DUMMYFUNCTION("""COMPUTED_VALUE"""),"KPRK MAJALENGKA 45400") -> KPRK MAJALENGKA 45400 | AO4: =IFERROR(__xludf.DUMMYFUNCTION("""COMPUTED_VALUE"""),"0308220037226") -> 0308220037226 | AP4: =IFERROR(__xludf.DUMMYFUNCTION("""COMPUTED_VALUE"""),"03082200372260001") -> 03082200372260001 | AT4: =IFERROR(__xludf.DUMMYFUNCTION("""COMPUTED_VALUE"""),"-69,735,611") -> -69,735,611 | AU4: =IFERROR(__xludf.DUMMYFUNCTION("""COMPUTED_VALUE"""),"108,2385667") -> 108,2385667 | AV4: =IFERROR(__xludf.DUMMYFUNCTION("""COMPUTED_VALUE"""),"ADA") -> ADA | AW4: =IFERROR(__xludf.DUMMYFUNCTION("""COMPUTED_VALUE"""),"ADA") -> ADA | BA4: =IFERROR(__xludf.DUMMYFUNCTION("""COMPUTED_VALUE"""),"ADA") -> ADA | BB4: =IFERROR(__xludf.DUMMYFUNCTION("""COMPUTED_VALUE"""),"ADA") -> ADA | BC4: =IFERROR(__xludf.DUMMYFUNCTION("""COMPUTED_VALUE"""),"ADA") -> ADA | BD4: =IFERROR(__xludf.DUMMYFUNCTION("""COMPUTED_VALUE"""),"ADA") -> ADA | BE4: =IFERROR(__xludf.DUMMYFUNCTION("""COMPUTED_VALUE"""),"ADA") -> ADA | BF4: =IFERROR(__xludf.DUMMYFUNCTION("""COMPUTED_VALUE"""),"ADA") -> ADA | BG4: =IFERROR(__xludf.DUMMYFUNCTION("""COMPUTED_VALUE"""),"ADA") -> ADA | BH4: =IFERROR(__xludf.DUMMYFUNCTION("""COMPUTED_VALUE"""),"CANON IP 2770") -> CANON IP 2770 | BI4: =IFERROR(__xludf.DUMMYFUNCTION("""COMPUTED_VALUE"""),"ADA") -> ADA | BJ4: =IFERROR(__xludf.DUMMYFUNCTION("""COMPUTED_VALUE"""),"KERTAS HVS") -> KERTAS HVS | BK4: =IFERROR(__xludf.DUMMYFUNCTION("""COMPUTED_VALUE"""),"TIDAK ADA") -> TIDAK ADA | BL4: =IFERROR(__xludf.DUMMYFUNCTION("""COMPUTED_VALUE"""),"DEPOSIT") -> DEPOSIT | BN4: =IFERROR(__xludf.DUMMYFUNCTION("""COMPUTED_VALUE"""),"panyalahan rt.003/004 kel.sinargalih kec.lemahsugih kab.majalengka") -> panyalahan rt.003/004 kel.sinargalih kec.lemahsugih kab.majalengka | BO4: =IFERROR(__xludf.DUMMYFUNCTION("""COMPUTED_VALUE"""),"3210017012890001") -> 3210017012890001 | BP4: =IFERROR(__xludf.DUMMYFUNCTION("""COMPUTED_VALUE"""),"30-12-1989") -> 30-12-1989 | BQ4: =IFERROR(__xludf.DUMMYFUNCTION("""COMPUTED_VALUE"""),"93.567.420.0-438.000") -> 93.567.420.0-438.000 | BR4: =IFERROR(__xludf.DUMMYFUNCTION("""COMPUTED_VALUE"""),"85351152899") -> 85351152899 | BS4: =IFERROR(__xludf.DUMMYFUNCTION("""COMPUTED_VALUE"""),"albyizladp93@gmail.com") -> albyizladp93@gmail.com | BT4: =IFERROR(__xludf.DUMMYFUNCTION("""COMPUTED_VALUE"""),"ISTRI PEMILIK SEBELUMNYA") -> ISTRI PEMILIK SEBELUMNYA | BU4: =IFERROR(__xludf.DUMMYFUNCTION("""COMPUTED_VALUE"""),"perangkat sudah lengkap,,petugas Pos siap membantu") -> perangkat sudah lengkap,,petugas Pos siap membantu | BV4: =IFERROR(__xludf.DUMMYFUNCTION("""COMPUTED_VALUE"""),"Panyalahan Rt03 Rw04 Ds. Sinargalih Kec. Lemahsugih Kab Majelangka Jawa Barat") -> Panyalahan Rt03 Rw04 Ds. Sinargalih Kec. Lemahsugih Kab Majelangka Jawa Barat
A5: =IFERROR(__xludf.DUMMYFUNCTION("""COMPUTED_VALUE"""),2.0) -> 2 | B5: =IFERROR(__xludf.DUMMYFUNCTION("""COMPUTED_VALUE""")," 11 Januari 2022") -> 11 Januari 2022 | C5: =IFERROR(__xludf.DUMMYFUNCTION("""COMPUTED_VALUE""")," 11 Januari 2022") -> 11 Januari 2022 | F5: =IFERROR(__xludf.DUMMYFUNCTION("""COMPUTED_VALUE"""),"7 OKTOBER 2022") -> 7 OKTOBER 2022 | G5: =IFERROR(__xludf.DUMMYFUNCTION("""COMPUTED_VALUE"""),44841.0) -> 44841 | I5: =IFERROR(__xludf.DUMMYFUNCTION("""COMPUTED_VALUE"""),"7/10/2022") -> 7/10/2022 | J5: =IFERROR(__xludf.DUMMYFUNCTION("""COMPUTED_VALUE"""),"10/10/2022") -> 10/10/2022 | P5: =IFERROR(__xludf.DUMMYFUNCTION("""COMPUTED_VALUE"""),"53BSPA06520JBHDT") -> 53BSPA06520JBHDT | Q5: =IFERROR(__xludf.DUMMYFUNCTION("""COMPUTED_VALUE"""),"ADVAN") -> ADVAN | R5: =IFERROR(__xludf.DUMMYFUNCTION("""COMPUTED_VALUE"""),"ADVAN") -> ADVAN | S5: =IFERROR(__xludf.DUMMYFUNCTION("""COMPUTED_VALUE"""),"Tri Berkah Komunika") -> Tri Berkah Komunika | T5: =IFERROR(__xludf.DUMMYFUNCTION("""COMPUTED_VALUE"""),"Ruby Residence No.5 Jalan Palgenep Margahayu Selatan Kab Bandung Jawa Barat") -> Ruby Residence No.5 Jalan Palgenep Margahayu Selatan Kab Bandung Jawa Barat | U5: =IFERROR(__xludf.DUMMYFUNCTION("""COMPUTED_VALUE""")," JL.AHMAD YANI 221-223, RUKO SEGITIGAMAS KOSAMBI BLOK F9") -> JL.AHMAD YANI 221-223, RUKO SEGITIGAMAS KOSAMBI BLOK F9 | V5: =IFERROR(__xludf.DUMMYFUNCTION("""COMPUTED_VALUE"""),"006/005") -> 006/005 | W5: =IFERROR(__xludf.DUMMYFUNCTION("""COMPUTED_VALUE"""),"Merdeka") -> Merdeka | X5: =IFERROR(__xludf.DUMMYFUNCTION("""COMPUTED_VALUE"""),"Sumur Bandung") -> Sumur Bandung | Y5: =IFERROR(__xludf.DUMMYFUNCTION("""COMPUTED_VALUE"""),"Kota Bandung") -> Kota Bandung | Z5: =IFERROR(__xludf.DUMMYFUNCTION("""COMPUTED_VALUE"""),"JAWA BARAT") -> JAWA BARAT | AA5: =IFERROR(__xludf.DUMMYFUNCTION("""COMPUTED_VALUE"""),"40113") -> 40113 | AB5: =IFERROR(__xludf.DUMMYFUNCTION("""COMPUTED_VALUE"""),"3204103105820004") -> 3204103105820004 | AC5: =IFERROR(__xludf.DUMMYFUNCTION("""COMPUTED_VALUE"""),"96.937.067.5-445.000 / 54.709.885.5-445.000") -> 96.937.067.5-445.000 / 54.709.885.5-445.000 | AD5: =IFERROR(__xludf.DUMMYFUNCTION("""COMPUTED_VALUE"""),"CUM - HDT") -> CUM - HDT | AE5: =IFERROR(__xludf.DUMMYFUNCTION("""COMPUTED_VALUE"""),"Sub Hidayat") -> Sub Hidayat | AF5: =IFERROR(__xludf.DUMMYFUNCTION("""COMPUTED_VALUE"""),"085225006163") -> 085225006163 | AG5: =IFERROR(__xludf.DUMMYFUNCTION("""COMPUTED_VALUE"""),"085225006163") -> 085225006163 | AH5: =IFERROR(__xludf.DUMMYFUNCTION("""COMPUTED_VALUE"""),"triberkahkomunika@gmail.com") -> triberkahkomunika@gmail.com | AI5: =IFERROR(__xludf.DUMMYFUNCTION("""COMPUTED_VALUE"""),"40113S2") -> 40113S2 | AJ5: =IFERROR(__xludf.DUMMYFUNCTION("""COMPUTED_VALUE"""),"620f44fde73af431f508dd63") -> 620f44fde73af431f508dd63 | AK5: =IFERROR(__xludf.DUMMYFUNCTION("""COMPUTED_VALUE"""),"dm40113s2") -> dm40113s2 | AL5: =IFERROR(__xludf.DUMMYFUNCTION("""COMPUTED_VALUE"""),"password") -> password | AM5: =IFERROR(__xludf.DUMMYFUNCTION("""COMPUTED_VALUE"""),"KANTOR REGIONAL III BANDUNG 40004") -> KANTOR REGIONAL III BANDUNG 40004 | AN5: =IFERROR(__xludf.DUMMYFUNCTION("""COMPUTED_VALUE"""),"SPP BANDUNG 40400") -> SPP BANDUNG 40400 | AO5: =IFERROR(__xludf.DUMMYFUNCTION("""COMPUTED_VALUE"""),"'0308220016199") -> '0308220016199 | AP5: =IFERROR(__xludf.DUMMYFUNCTION("""COMPUTED_VALUE"""),"03082200161990001") -> 03082200161990001 | AT5: =IFERROR(__xludf.DUMMYFUNCTION("""COMPUTED_VALUE"""),"-6.9192693") -> -6.9192693 | AU5: =IFERROR(__xludf.DUMMYFUNCTION("""COMPUTED_VALUE"""),"107.6267906") -> 107.6267906 | AV5: =IFERROR(__xludf.DUMMYFUNCTION("""COMPUTED_VALUE"""),"BELUM ADA") -> BELUM ADA | AW5: =IFERROR(__xludf.DUMMYFUNCTION("""COMPUTED_VALUE"""),"ADA") -> ADA | BA5: =IFERROR(__xludf.DUMMYFUNCTION("""COMPUTED_VALUE"""),"ADA") -> ADA | BB5: =IFERROR(__xludf.DUMMYFUNCTION("""COMPUTED_VALUE"""),"ADA") -> ADA | BC5: =IFERROR(__xludf.DUMMYFUNCTION("""COMPUTED_VALUE"""),"ADA") -> ADA | BD5: =IFERROR(__xludf.DUMMYFUNCTION("""COMPUTED_VALUE"""),"ADA") -> ADA | BE5: =IFERROR(__xludf.DUMMYFUNCTION("""COMPUTED_VALUE"""),"ADA") -> ADA | BF5: =IFERROR(__xludf.DUMMYFUNCTION("""COMPUTED_VALUE"""),"ADA") -> ADA | BG5: =IFERROR(__xludf.DUMMYFUNCTION("""COMPUTED_VALUE"""),"ADA") -> ADA | BH5: =IFERROR(__xludf.DUMMYFUNCTION("""COMPUTED_VALUE"""),"ZJIANG 9200 BLUETOOTH") -> ZJIANG 9200 BLUETOOTH | BI5: =IFERROR(__xludf.DUMMYFUNCTION("""COMPUTED_VALUE"""),"ADA") -> ADA | BJ5: =IFERROR(__xludf.DUMMYFUNCTION("""COMPUTED_VALUE"""),"ADA") -> ADA | BK5: =IFERROR(__xludf.DUMMYFUNCTION("""COMPUTED_VALUE"""),"TIDAK ADA") -> TIDAK ADA | BL5: =IFERROR(__xludf.DUMMYFUNCTION("""COMPUTED_VALUE"""),"DEPOSIT") -> DEPOSIT | BV5: =IFERROR(__xludf.DUMMYFUNCTION("""COMPUTED_VALUE"""),"Ruby Residence No.5 Jalan Palgenep Margahayu Selatan Kab Bandung Jawa Barat") -> Ruby Residence No.5 Jalan Palgenep Margahayu Selatan Kab Bandung Jawa Barat
A6: =IFERROR(__xludf.DUMMYFUNCTION("""COMPUTED_VALUE"""),3.0) -> 3 | B6: =IFERROR(__xludf.DUMMYFUNCTION("""COMPUTED_VALUE""")," 11 Januari 2022") -> 11 Januari 2022 | C6: =IFERROR(__xludf.DUMMYFUNCTION("""COMPUTED_VALUE""")," 11 Januari 2022") -> 11 Januari 2022 | F6: =IFERROR(__xludf.DUMMYFUNCTION("""COMPUTED_VALUE"""),"7 OKTOBER 2022") -> 7 OKTOBER 2022 | G6: =IFERROR(__xludf.DUMMYFUNCTION("""COMPUTED_VALUE"""),44789.0) -> 44789 | I6: =IFERROR(__xludf.DUMMYFUNCTION("""COMPUTED_VALUE"""),"1/10/2022") -> 1/10/2022 | J6: =IFERROR(__xludf.DUMMYFUNCTION("""COMPUTED_VALUE"""),"23/08/2022") -> 23/08/2022 | P6: =IFERROR(__xludf.DUMMYFUNCTION("""COMPUTED_VALUE"""),"53BSPA23563JBRND") -> 53BSPA23563JBRND | Q6: =IFERROR(__xludf.DUMMYFUNCTION("""COMPUTED_VALUE"""),"IND") -> IND | R6: =IFERROR(__xludf.DUMMYFUNCTION("""COMPUTED_VALUE"""),"KARYANO") -> KARYANO | S6: =IFERROR(__xludf.DUMMYFUNCTION("""COMPUTED_VALUE"""),"Karyano") -> Karyano | T6: =IFERROR(__xludf.DUMMYFUNCTION("""COMPUTED_VALUE"""),"Desa Panjalin Lor Rt 02 Rw 01 Kel Panjalin Lor Kec Sumber Jaya Kab Majalengka Jawa Barat 45455") -> Desa Panjalin Lor Rt 02 Rw 01 Kel Panjalin Lor Kec Sumber Jaya Kab Majalengka Jawa Barat 45455 | U6: =IFERROR(__xludf.DUMMYFUNCTION("""COMPUTED_VALUE"""),"DESA PANJALIN LOR RT 02 RW 01") -> DESA PANJALIN LOR RT 02 RW 01 | V6: =IFERROR(__xludf.DUMMYFUNCTION("""COMPUTED_VALUE"""),"002/001") -> 002/001 | W6: =IFERROR(__xludf.DUMMYFUNCTION("""COMPUTED_VALUE"""),"PANJALIN LOR") -> PANJALIN LOR | X6: =IFERROR(__xludf.DUMMYFUNCTION("""COMPUTED_VALUE"""),"SUMBER JAYA") -> SUMBER JAYA | Y6: =IFERROR(__xludf.DUMMYFUNCTION("""COMPUTED_VALUE"""),"KAB. MAJALENGKA") -> KAB. MAJALENGKA | Z6: =IFERROR(__xludf.DUMMYFUNCTION("""COMPUTED_VALUE"""),"JAWA BARAT") -> JAWA BARAT | AA6: =IFERROR(__xludf.DUMMYFUNCTION("""COMPUTED_VALUE"""),"45455") -> 45455 | AB6: =IFERROR(__xludf.DUMMYFUNCTION("""COMPUTED_VALUE"""),"3210171809750021") -> 3210171809750021 | AC6: =IFERROR(__xludf.DUMMYFUNCTION("""COMPUTED_VALUE"""),"95.514.434.0-438.000") -> 95.514.434.0-438.000 | AD6: =IFERROR(__xludf.DUMMYFUNCTION("""COMPUTED_VALUE"""),"CUM - NDS") -> CUM - NDS | AE6: =IFERROR(__xludf.DUMMYFUNCTION("""COMPUTED_VALUE"""),"SUB NURUL DIMAS") -> SUB NURUL DIMAS | AF6: =IFERROR(__xludf.DUMMYFUNCTION("""COMPUTED_VALUE"""),"081324512860") -> 081324512860 | AG6: =IFERROR(__xludf.DUMMYFUNCTION("""COMPUTED_VALUE"""),"081324512860") -> 081324512860 | AH6: =IFERROR(__xludf.DUMMYFUNCTION("""COMPUTED_VALUE"""),"karyano1975@gmail.com") -> karyano1975@gmail.com | AI6: =IFERROR(__xludf.DUMMYFUNCTION("""COMPUTED_VALUE"""),"45455S2") -> 45455S2 | AJ6: =IFERROR(__xludf.DUMMYFUNCTION("""COMPUTED_VALUE"""),"6211a3ce5bb90f52364e0b09") -> 6211a3ce5bb90f52364e0b09 | AK6: =IFERROR(__xludf.DUMMYFUNCTION("""COMPUTED_VALUE"""),"dm45455s2") -> dm45455s2 | AL6: =IFERROR(__xludf.DUMMYFUNCTION("""COMPUTED_VALUE"""),"password") -> password | AM6: =IFERROR(__xludf.DUMMYFUNCTION("""COMPUTED_VALUE"""),"KANTOR REGIONAL III BANDUNG 40004") -> KANTOR REGIONAL III BANDUNG 40004 | AN6: =IFERROR(__xludf.DUMMYFUNCTION("""COMPUTED_VALUE"""),"KPRK MAJALENGKA 45400") -> KPRK MAJALENGKA 45400 | AO6: =IFERROR(__xludf.DUMMYFUNCTION("""COMPUTED_VALUE"""),"0208220052716") -> 0208220052716 | AP6: =IFERROR(__xludf.DUMMYFUNCTION("""COMPUTED_VALUE"""),"02082200527160001") -> 02082200527160001 | AT6: =IFERROR(__xludf.DUMMYFUNCTION("""COMPUTED_VALUE"""),"-66,841,102") -> -66,841,102 | AU6: =IFERROR(__xludf.DUMMYFUNCTION("""COMPUTED_VALUE"""),"1,083,501,149") -> 1,083,501,149 | AV6: =IFERROR(__xludf.DUMMYFUNCTION("""COMPUTED_VALUE"""),"ADA") -> ADA | AW6: =IFERROR(__xludf.DUMMYFUNCTION("""COMPUTED_VALUE"""),"ADA") -> ADA | BA6: =IFERROR(__xludf.DUMMYFUNCTION("""COMPUTED_VALUE"""),"ADA") -> ADA | BB6: =IFERROR(__xludf.DUMMYFUNCTION("""COMPUTED_VALUE"""),"ADA") -> ADA | BC6: =IFERROR(__xludf.DUMMYFUNCTION("""COMPUTED_VALUE"""),"ADA") -> ADA | BD6: =IFERROR(__xludf.DUMMYFUNCTION("""COMPUTED_VALUE"""),"ADA") -> ADA | BE6: =IFERROR(__xludf.DUMMYFUNCTION("""COMPUTED_VALUE"""),"ADA") -> ADA | BF6: =IFERROR(__xludf.DUMMYFUNCTION("""COMPUTED_VALUE"""),"ADA") -> ADA | BG6: =IFERROR(__xludf.DUMMYFUNCTION("""COMPUTED_VALUE"""),"ADA") -> ADA | BH6: =IFERROR(__xludf.DUMMYFUNCTION("""COMPUTED_VALUE"""),"CANON G1010") -> CANON G1010 | BI6: =IFERROR(__xludf.DUMMYFUNCTION("""COMPUTED_VALUE"""),"ADA") -> ADA | BJ6: =IFERROR(__xludf.DUMMYFUNCTION("""COMPUTED_VALUE"""),"KERTAS HVS") -> KERTAS HVS | BK6: =IFERROR(__xludf.DUMMYFUNCTION("""COMPUTED_VALUE"""),"TIDAK ADA") -> TIDAK ADA | BL6: =IFERROR(__xludf.DUMMYFUNCTION("""COMPUTED_VALUE"""),"PLAFON") -> PLAFON | BV6: =IFERROR(__xludf.DUMMYFUNCTION("""COMPUTED_VALUE"""),"Desa Panjalin Lor Rt 02 Rw 01 Kel Panjalin Lor Kec Sumber Jaya Kab Majalengka Jawa Barat 45455") -> Desa Panjalin Lor Rt 02 Rw 01 Kel Panjalin Lor Kec Sumber Jaya Kab Majalengka Jawa Barat 45455
A7: =IFERROR(__xludf.DUMMYFUNCTION("""COMPUTED_VALUE"""),4.0) -> 4 | B7: =IFERROR(__xludf.DUMMYFUNCTION("""COMPUTED_VALUE"""),"20 Januari 2022") -> 20 Januari 2022 | C7: =IFERROR(__xludf.DUMMYFUNCTION("""COMPUTED_VALUE"""),"20 Januari 2022") -> 20 Januari 2022 | F7: =IFERROR(__xludf.DUMMYFUNCTION("""COMPUTED_VALUE"""),"6 OKTOBER 2022") -> 6 OKTOBER 2022 | G7: =IFERROR(__xludf.DUMMYFUNCTION("""COMPUTED_VALUE"""),44839.0) -> 44839 | I7: =IFERROR(__xludf.DUMMYFUNCTION("""COMPUTED_VALUE"""),"6/10/2022") -> 6/10/2022 | J7: =IFERROR(__xludf.DUMMYFUNCTION("""COMPUTED_VALUE"""),"23/12/2022") -> 23/12/2022 | P7: =IFERROR(__xludf.DUMMYFUNCTION("""COMPUTED_VALUE"""),"53BSPA16129JBNDS") -> 53BSPA16129JBNDS | Q7: =IFERROR(__xludf.DUMMYFUNCTION("""COMPUTED_VALUE"""),"DODON CELL") -> DODON CELL | R7: =IFERROR(__xludf.DUMMYFUNCTION("""COMPUTED_VALUE"""),"DODON CELL") -> DODON CELL | S7: =IFERROR(__xludf.DUMMYFUNCTION("""COMPUTED_VALUE"""),"Suhardi") -> Suhardi | T7: =IFERROR(__xludf.DUMMYFUNCTION("""COMPUTED_VALUE"""),"Dalam Desa Rt 001 Rw 001 Kel Pakembangan Kec Garawangi Kab Kuningan Jawa Barat 45571") -> Dalam Desa Rt 001 Rw 001 Kel Pakembangan Kec Garawangi Kab Kuningan Jawa Barat 45571 | U7: =IFERROR(__xludf.DUMMYFUNCTION("""COMPUTED_VALUE"""),"Dalam Desa Rt 001 RW 001 Kel Pakembangan Kec Garawangi Kab Kuningan Jawa Barat 45571") -> Dalam Desa Rt 001 RW 001 Kel Pakembangan Kec Garawangi Kab Kuningan Jawa Barat 45571 | V7: =IFERROR(__xludf.DUMMYFUNCTION("""COMPUTED_VALUE"""),"001/001") -> 001/001 | W7: =IFERROR(__xludf.DUMMYFUNCTION("""COMPUTED_VALUE"""),"Pakembangan") -> Pakembangan | X7: =IFERROR(__xludf.DUMMYFUNCTION("""COMPUTED_VALUE"""),"Garawangi") -> Garawangi | Y7: =IFERROR(__xludf.DUMMYFUNCTION("""COMPUTED_VALUE"""),"Kuningan") -> Kuningan | Z7: =IFERROR(__xludf.DUMMYFUNCTION("""COMPUTED_VALUE"""),"JAWA BARAT") -> JAWA BARAT | AA7: =IFERROR(__xludf.DUMMYFUNCTION("""COMPUTED_VALUE"""),"45571") -> 45571 | AB7: =IFERROR(__xludf.DUMMYFUNCTION("""COMPUTED_VALUE"""),"3208081507750006") -> 3208081507750006 | AC7: =IFERROR(__xludf.DUMMYFUNCTION("""COMPUTED_VALUE"""),"82.640.029.3-438.000") -> 82.640.029.3-438.000 | AD7: =IFERROR(__xludf.DUMMYFUNCTION("""COMPUTED_VALUE"""),"CUM - NDS") -> CUM - NDS | AE7: =IFERROR(__xludf.DUMMYFUNCTION("""COMPUTED_VALUE"""),"SUB NURUL DIMAS") -> SUB NURUL DIMAS | AF7: =IFERROR(__xludf.DUMMYFUNCTION("""COMPUTED_VALUE"""),"087893435753") -> 087893435753 | AG7: =IFERROR(__xludf.DUMMYFUNCTION("""COMPUTED_VALUE"""),"087893435753") -> 087893435753 | AH7: =IFERROR(__xludf.DUMMYFUNCTION("""COMPUTED_VALUE"""),"dodoncell@gmail.com") -> dodoncell@gmail.com | AI7: =IFERROR(__xludf.DUMMYFUNCTION("""COMPUTED_VALUE"""),"45571S1") -> 45571S1 | AJ7: =IFERROR(__xludf.DUMMYFUNCTION("""COMPUTED_VALUE"""),"6210ec2857f5ac485347ddd9") -> 6210ec2857f5ac485347ddd9 | AK7: =IFERROR(__xludf.DUMMYFUNCTION("""COMPUTED_VALUE"""),"dm45571s1") -> dm45571s1 | AL7: =IFERROR(__xludf.DUMMYFUNCTION("""COMPUTED_VALUE"""),"password") -> password | AM7: =IFERROR(__xludf.DUMMYFUNCTION("""COMPUTED_VALUE"""),"KANTOR REGIONAL III BANDUNG 40004") -> KANTOR REGIONAL III BANDUNG 40004 | AN7: =IFERROR(__xludf.DUMMYFUNCTION("""COMPUTED_VALUE"""),"KPRK KUNINGAN 45500") -> KPRK KUNINGAN 45500 | AO7: =IFERROR(__xludf.DUMMYFUNCTION("""COMPUTED_VALUE"""),"0208220057532") -> 0208220057532 | AP7: =IFERROR(__xludf.DUMMYFUNCTION("""COMPUTED_VALUE"""),"02082200575320001") -> 02082200575320001 | AT7: =IFERROR(__xludf.DUMMYFUNCTION("""COMPUTED_VALUE"""),"-70,135,689") -> -70,135,689 | AU7: =IFERROR(__xludf.DUMMYFUNCTION("""COMPUTED_VALUE"""),"1,085,190,858") -> 1,085,190,858 | AV7: =IFERROR(__xludf.DUMMYFUNCTION("""COMPUTED_VALUE"""),"ADA") -> ADA | AW7: =IFERROR(__xludf.DUMMYFUNCTION("""COMPUTED_VALUE"""),"ADA") -> ADA | BA7: =IFERROR(__xludf.DUMMYFUNCTION("""COMPUTED_VALUE"""),"ADA") -> ADA | BB7: =IFERROR(__xludf.DUMMYFUNCTION("""COMPUTED_VALUE"""),"ADA") -> ADA | BC7: =IFERROR(__xludf.DUMMYFUNCTION("""COMPUTED_VALUE"""),"ADA") -> ADA | BD7: =IFERROR(__xludf.DUMMYFUNCTION("""COMPUTED_VALUE"""),"ADA") -> ADA | BE7: =IFERROR(__xludf.DUMMYFUNCTION("""COMPUTED_VALUE"""),"ADA") -> ADA | BF7: =IFERROR(__xludf.DUMMYFUNCTION("""COMPUTED_VALUE"""),"ADA") -> ADA | BG7: =IFERROR(__xludf.DUMMYFUNCTION("""COMPUTED_VALUE"""),"ADA") -> ADA | BH7: =IFERROR(__xludf.DUMMYFUNCTION("""COMPUTED_VALUE"""),"BLUEPRINT") -> BLUEPRINT | BI7: =IFERROR(__xludf.DUMMYFUNCTION("""COMPUTED_VALUE"""),"ADA") -> ADA | BJ7: =IFERROR(__xludf.DUMMYFUNCTION("""COMPUTED_VALUE"""),"STICKER") -> STICKER | BK7: =IFERROR(__xludf.DUMMYFUNCTION("""COMPUTED_VALUE"""),"ADA") -> ADA | BL7: =IFERROR(__xludf.DUMMYFUNCTION("""COMPUTED_VALUE"""),"DEPOSIT") -> DEPOSIT | BV7: =IFERROR(__xludf.DUMMYFUNCTION("""COMPUTED_VALUE"""),"Dalam Desa Rt 001 Rw 001 Kel Pakembangan Kec Garawangi Kab Kuningan Jawa Barat 45571") -> Dalam Desa Rt 001 Rw 001 Kel Pakembangan Kec Garawangi Kab Kuningan Jawa Barat 45571
A8: =IFERROR(__xludf.DUMMYFUNCTION("""COMPUTED_VALUE"""),5.0) -> 5 | B8: =IFERROR(__xludf.DUMMYFUNCTION("""COMPUTED_VALUE"""),"11 Januari 2022") -> 11 Januari 2022 | C8: =IFERROR(__xludf.DUMMYFUNCTION("""COMPUTED_VALUE"""),"11 Januari 2022") -> 11 Januari 2022 | F8: =IFERROR(__xludf.DUMMYFUNCTION("""COMPUTED_VALUE"""),"25-08-2022") -> 25-08-2022 | G8: =IFERROR(__xludf.DUMMYFUNCTION("""COMPUTED_VALUE"""),44799.0) -> 44799 | I8: =IFERROR(__xludf.DUMMYFUNCTION("""COMPUTED_VALUE"""),"25-08-2022") -> 25-08-2022 | J8: =IFERROR(__xludf.DUMMYFUNCTION("""COMPUTED_VALUE"""),"12/10/2022") -> 12/10/2022 | P8: =IFERROR(__xludf.DUMMYFUNCTION("""COMPUTED_VALUE"""),"KH3SPA12903JTAMD") -> KH3SPA12903JTAMD | Q8: =IFERROR(__xludf.DUMMYFUNCTION("""COMPUTED_VALUE"""),"CV. AlKautsar") -> CV. AlKautsar | R8: =IFERROR(__xludf.DUMMYFUNCTION("""COMPUTED_VALUE"""),"AL KAUTSAR") -> AL KAUTSAR | S8: =IFERROR(__xludf.DUMMYFUNCTION("""COMPUTED_VALUE"""),"Sundari") -> Sundari | T8: =IFERROR(__xludf.DUMMYFUNCTION("""COMPUTED_VALUE"""),"Kadirejo Rt 50/17, Mranggen, Jatinom Klaten Jawa Tengah 57481") -> Kadirejo Rt 50/17, Mranggen, Jatinom Klaten Jawa Tengah 57481 | U8: =IFERROR(__xludf.DUMMYFUNCTION("""COMPUTED_VALUE"""),"KADIREJO RT 50/17, MRANGGEN, JATINOM KLATEN JAWA TENGAH 57481") -> KADIREJO RT 50/17, MRANGGEN, JATINOM KLATEN JAWA TENGAH 57481 | V8: =IFERROR(__xludf.DUMMYFUNCTION("""COMPUTED_VALUE"""),"50/17") -> 50/17 | W8: =IFERROR(__xludf.DUMMYFUNCTION("""COMPUTED_VALUE"""),"MRANGGEN") -> MRANGGEN | X8: =IFERROR(__xludf.DUMMYFUNCTION("""COMPUTED_VALUE"""),"JATINOM") -> JATINOM | Y8: =IFERROR(__xludf.DUMMYFUNCTION("""COMPUTED_VALUE"""),"Klaten") -> Klaten | Z8: =IFERROR(__xludf.DUMMYFUNCTION("""COMPUTED_VALUE"""),"JAWA TENGAH") -> JAWA TENGAH | AA8: =IFERROR(__xludf.DUMMYFUNCTION("""COMPUTED_VALUE"""),"57481") -> 57481 | AB8: =IFERROR(__xludf.DUMMYFUNCTION("""COMPUTED_VALUE"""),"3310206709810002") -> 3310206709810002 | AC8: =IFERROR(__xludf.DUMMYFUNCTION("""COMPUTED_VALUE"""),"57.943.318.6-525.000") -> 57.943.318.6-525.000 | AD8: =IFERROR(__xludf.DUMMYFUNCTION("""COMPUTED_VALUE"""),"CUM - AMI") -> CUM - AMI | AE8: =IFERROR(__xludf.DUMMYFUNCTION("""COMPUTED_VALUE"""),"SUB AMINUDDIN") -> SUB AMINUDDIN | AF8: =IFERROR(__xludf.DUMMYFUNCTION("""COMPUTED_VALUE"""),"081329294335") -> 081329294335 | AG8: =IFERROR(__xludf.DUMMYFUNCTION("""COMPUTED_VALUE"""),"081329294335") -> 081329294335 | AH8: =IFERROR(__xludf.DUMMYFUNCTION("""COMPUTED_VALUE"""),"samidi.klt@gmail.com") -> samidi.klt@gmail.com | AI8: =IFERROR(__xludf.DUMMYFUNCTION("""COMPUTED_VALUE"""),"57481S3") -> 57481S3 | AJ8: =IFERROR(__xludf.DUMMYFUNCTION("""COMPUTED_VALUE"""),"61f253f47fc1ac7560092ab3") -> 61f253f47fc1ac7560092ab3 | AK8: =IFERROR(__xludf.DUMMYFUNCTION("""COMPUTED_VALUE"""),"dm57481s3") -> dm57481s3 | AL8: =IFERROR(__xludf.DUMMYFUNCTION("""COMPUTED_VALUE"""),"password") -> password | AM8: =IFERROR(__xludf.DUMMYFUNCTION("""COMPUTED_VALUE"""),"KANTOR REGIONAL IV SEMARANG 50004") -> KANTOR REGIONAL IV SEMARANG 50004 | AN8: =IFERROR(__xludf.DUMMYFUNCTION("""COMPUTED_VALUE"""),"KPRK KLATEN 57400") -> KPRK KLATEN 57400 | AO8: =IFERROR(__xludf.DUMMYFUNCTION("""COMPUTED_VALUE"""),"010822006168") -> 010822006168 | AP8: =IFERROR(__xludf.DUMMYFUNCTION("""COMPUTED_VALUE"""),"01082200561680001") -> 01082200561680001 | AT8: =IFERROR(__xludf.DUMMYFUNCTION("""COMPUTED_VALUE"""),"S 7°40'16.2336"" ") -> S 7°40'16.2336" | AU8: =IFERROR(__xludf.DUMMYFUNCTION("""COMPUTED_VALUE"""),"E 110°34'45.4476"" ") -> E 110°34'45.4476" | AV8: =IFERROR(__xludf.DUMMYFUNCTION("""COMPUTED_VALUE"""),"ADA") -> ADA | AW8: =IFERROR(__xludf.DUMMYFUNCTION("""COMPUTED_VALUE"""),"ADA") -> ADA | BA8: =IFERROR(__xludf.DUMMYFUNCTION("""COMPUTED_VALUE"""),"ADA") -> ADA | BB8: =IFERROR(__xludf.DUMMYFUNCTION("""COMPUTED_VALUE"""),"ADA") -> ADA | BC8: =IFERROR(__xludf.DUMMYFUNCTION("""COMPUTED_VALUE"""),"ADA") -> ADA | BD8: =IFERROR(__xludf.DUMMYFUNCTION("""COMPUTED_VALUE"""),"ADA") -> ADA | BE8: =IFERROR(__xludf.DUMMYFUNCTION("""COMPUTED_VALUE"""),"ADA") -> ADA | BF8: =IFERROR(__xludf.DUMMYFUNCTION("""COMPUTED_VALUE"""),"ADA") -> ADA | BG8: =IFERROR(__xludf.DUMMYFUNCTION("""COMPUTED_VALUE"""),"ADA") -> ADA | BH8: =IFERROR(__xludf.DUMMYFUNCTION("""COMPUTED_VALUE"""),"EPPOS EP-9200U") -> EPPOS EP-9200U | BI8: =IFERROR(__xludf.DUMMYFUNCTION("""COMPUTED_VALUE"""),"ADA") -> ADA | BJ8: =IFERROR(__xludf.DUMMYFUNCTION("""COMPUTED_VALUE"""),"TIDAK ADA") -> TIDAK ADA | BK8: =IFERROR(__xludf.DUMMYFUNCTION("""COMPUTED_VALUE"""),"TIDAK ADA") -> TIDAK ADA | BL8: =IFERROR(__xludf.DUMMYFUNCTION("""COMPUTED_VALUE"""),"PLAFON") -> PLAFON | BV8: =IFERROR(__xludf.DUMMYFUNCTION("""COMPUTED_VALUE"""),"Kadirejo Rt 50/17, Mranggen, Jatinom Klaten Jawa Tengah 57481") -> Kadirejo Rt 50/17, Mranggen, Jatinom Klaten Jawa Tengah 57481
A9: =IFERROR(__xludf.DUMMYFUNCTION("""COMPUTED_VALUE"""),6.0) -> 6 | B9: =IFERROR(__xludf.DUMMYFUNCTION("""COMPUTED_VALUE"""),"11 Januari 2022") -> 11 Januari 2022 | C9: =IFERROR(__xludf.DUMMYFUNCTION("""COMPUTED_VALUE"""),"11 Januari 2022") -> 11 Januari 2022 | F9: =IFERROR(__xludf.DUMMYFUNCTION("""COMPUTED_VALUE"""),"16 AGUSTUS 2022") -> 16 AGUSTUS 2022 | G9: =IFERROR(__xludf.DUMMYFUNCTION("""COMPUTED_VALUE"""),44789.0) -> 44789 | I9: =IFERROR(__xludf.DUMMYFUNCTION("""COMPUTED_VALUE"""),"16-08-2022") -> 16-08-2022 | J9: =IFERROR(__xludf.DUMMYFUNCTION("""COMPUTED_VALUE"""),"16-08-2022") -> 16-08-2022 | P9: =IFERROR(__xludf.DUMMYFUNCTION("""COMPUTED_VALUE"""),"53BSPA29473JBEEN") -> 53BSPA29473JBEEN | Q9: =IFERROR(__xludf.DUMMYFUNCTION("""COMPUTED_VALUE"""),"PRI GROUP") -> PRI GROUP | R9: =IFERROR(__xludf.DUMMYFUNCTION("""COMPUTED_VALUE"""),"PRI GROUP") -> PRI GROUP | S9: =IFERROR(__xludf.DUMMYFUNCTION("""COMPUTED_VALUE"""),"Supriyanto Amd, A.Md") -> Supriyanto Amd, A.Md | T9: =IFERROR(__xludf.DUMMYFUNCTION("""COMPUTED_VALUE"""),"Jl. Ikhlas No. 11A Kel. Binjai Kec. Medan Denai Medan Sumatera Utara 20228") -> Jl. Ikhlas No. 11A Kel. Binjai Kec. Medan Denai Medan Sumatera Utara 20228 | U9: =IFERROR(__xludf.DUMMYFUNCTION("""COMPUTED_VALUE"""),"JL. IKHLAS NO. 11A KEL. BINJAI KEC. MEDAN DENAI Medan Sumatera Utara 20228") -> JL. IKHLAS NO. 11A KEL. BINJAI KEC. MEDAN DENAI Medan Sumatera Utara 20228 | W9: =IFERROR(__xludf.DUMMYFUNCTION("""COMPUTED_VALUE"""),"BINJAI") -> BINJAI | X9: =IFERROR(__xludf.DUMMYFUNCTION("""COMPUTED_VALUE"""),"MEDAN DENAI") -> MEDAN DENAI | Y9: =IFERROR(__xludf.DUMMYFUNCTION("""COMPUTED_VALUE"""),"medan") -> medan | Z9: =IFERROR(__xludf.DUMMYFUNCTION("""COMPUTED_VALUE"""),"SUMATERA UTARA") -> SUMATERA UTARA | AA9: =IFERROR(__xludf.DUMMYFUNCTION("""COMPUTED_VALUE"""),"20228") -> 20228 | AB9: =IFERROR(__xludf.DUMMYFUNCTION("""COMPUTED_VALUE"""),"1271041101850009") -> 1271041101850009 | AC9: =IFERROR(__xludf.DUMMYFUNCTION("""COMPUTED_VALUE"""),"25.246.029.0-112.000") -> 25.246.029.0-112.000 | AD9: =IFERROR(__xludf.DUMMYFUNCTION("""COMPUTED_VALUE"""),"CUM - EEN") -> CUM - EEN | AE9: =IFERROR(__xludf.DUMMYFUNCTION("""COMPUTED_VALUE"""),"SUB EEN") -> SUB EEN | AF9: =IFERROR(__xludf.DUMMYFUNCTION("""COMPUTED_VALUE"""),"082168041162 / 081990448804") -> 082168041162 / 081990448804 | AG9: =IFERROR(__xludf.DUMMYFUNCTION("""COMPUTED_VALUE"""),"082168041162") -> 082168041162 | AH9: =IFERROR(__xludf.DUMMYFUNCTION("""COMPUTED_VALUE"""),"supriy.pri@gmail.com") -> supriy.pri@gmail.com | AI9: =IFERROR(__xludf.DUMMYFUNCTION("""COMPUTED_VALUE"""),"20228S3") -> 20228S3 | AJ9: =IFERROR(__xludf.DUMMYFUNCTION("""COMPUTED_VALUE"""),"620e17d0498b976fad115b28") -> 620e17d0498b976fad115b28 | AK9: =IFERROR(__xludf.DUMMYFUNCTION("""COMPUTED_VALUE"""),"dm20228s3") -> dm20228s3 | AL9: =IFERROR(__xludf.DUMMYFUNCTION("""COMPUTED_VALUE"""),"password") -> password | AM9: =IFERROR(__xludf.DUMMYFUNCTION("""COMPUTED_VALUE"""),"KANTOR REGIONAL I MEDAN 20004") -> KANTOR REGIONAL I MEDAN 20004 | AN9: =IFERROR(__xludf.DUMMYFUNCTION("""COMPUTED_VALUE"""),"SPP MEDAN 20900") -> SPP MEDAN 20900 | AO9: =IFERROR(__xludf.DUMMYFUNCTION("""COMPUTED_VALUE"""),"0208220034165") -> 0208220034165 | AP9: =IFERROR(__xludf.DUMMYFUNCTION("""COMPUTED_VALUE"""),"02082200341650001") -> 02082200341650001 | AT9: =IFERROR(__xludf.DUMMYFUNCTION("""COMPUTED_VALUE"""),"35,718,501.98") -> 35,718,501.98 | AU9: =IFERROR(__xludf.DUMMYFUNCTION("""COMPUTED_VALUE"""),"98,721,141") -> 98,721,141 | AV9: =IFERROR(__xludf.DUMMYFUNCTION("""COMPUTED_VALUE"""),"ADA") -> ADA | AW9: =IFERROR(__xludf.DUMMYFUNCTION("""COMPUTED_VALUE"""),"ADA") -> ADA | BA9: =IFERROR(__xludf.DUMMYFUNCTION("""COMPUTED_VALUE"""),"ADA") -> ADA | BB9: =IFERROR(__xludf.DUMMYFUNCTION("""COMPUTED_VALUE"""),"ADA") -> ADA | BC9: =IFERROR(__xludf.DUMMYFUNCTION("""COMPUTED_VALUE"""),"ADA") -> ADA | BD9: =IFERROR(__xludf.DUMMYFUNCTION("""COMPUTED_VALUE"""),"ADA") -> ADA | BE9: =IFERROR(__xludf.DUMMYFUNCTION("""COMPUTED_VALUE"""),"ADA") -> ADA | BF9: =IFERROR(__xludf.DUMMYFUNCTION("""COMPUTED_VALUE"""),"ADA") -> ADA | BG9: =IFERROR(__xludf.DUMMYFUNCTION("""COMPUTED_VALUE"""),"ADA") -> ADA | BH9: =IFERROR(__xludf.DUMMYFUNCTION("""COMPUTED_VALUE"""),"CANON MP237") -> CANON MP237 | BI9: =IFERROR(__xludf.DUMMYFUNCTION("""COMPUTED_VALUE"""),"ADA") -> ADA | BJ9: =IFERROR(__xludf.DUMMYFUNCTION("""COMPUTED_VALUE"""),"KERTAS HVS") -> KERTAS HVS | BK9: =IFERROR(__xludf.DUMMYFUNCTION("""COMPUTED_VALUE"""),"TIDAK ADA") -> TIDAK ADA | BL9: =IFERROR(__xludf.DUMMYFUNCTION("""COMPUTED_VALUE"""),"PLAFON") -> PLAFON | BV9: =IFERROR(__xludf.DUMMYFUNCTION("""COMPUTED_VALUE"""),"Jl. Ikhlas No. 11A Kel. Binjai Kec. Medan Denai Medan Sumatera Utara 20228") -> Jl. Ikhlas No. 11A Kel. Binjai Kec. Medan Denai Medan Sumatera Utara 20228
A10: =IFERROR(__xludf.DUMMYFUNCTION("""COMPUTED_VALUE"""),7.0) -> 7 | B10: =IFERROR(__xludf.DUMMYFUNCTION("""COMPUTED_VALUE"""),"11 Januari 2022") -> 11 Januari 2022 | C10: =IFERROR(__xludf.DUMMYFUNCTION("""COMPUTED_VALUE"""),"11 Januari 2022") -> 11 Januari 2022 | P10: =IFERROR(__xludf.DUMMYFUNCTION("""COMPUTED_VALUE"""),"52BSPA22777JTKRS") -> 52BSPA22777JTKRS | Q10: =IFERROR(__xludf.DUMMYFUNCTION("""COMPUTED_VALUE"""),"Barokah Expres ") -> Barokah Expres | R10: =IFERROR(__xludf.DUMMYFUNCTION("""COMPUTED_VALUE"""),"BAROKAH EXPRESS") -> BAROKAH EXPRESS | S10: =IFERROR(__xludf.DUMMYFUNCTION("""COMPUTED_VALUE"""),"Tegar") -> Tegar | T10: =IFERROR(__xludf.DUMMYFUNCTION("""COMPUTED_VALUE"""),"Perumahan New Grand Residence Blok O5, Kedung Gede Kec Banyumas Kab Banyumas Jawa Tengah") -> Perumahan New Grand Residence Blok O5, Kedung Gede Kec Banyumas Kab Banyumas Jawa Tengah | U10: =IFERROR(__xludf.DUMMYFUNCTION("""COMPUTED_VALUE"""),"PERUMAHAN NEW GRAND RESIDENCE BLOK O5, KEDUNG GEDE KEC BANYUMAS KAB BANYUMAS JAWA TENGAH") -> PERUMAHAN NEW GRAND RESIDENCE BLOK O5, KEDUNG GEDE KEC BANYUMAS KAB BANYUMAS JAWA TENGAH | V10: =IFERROR(__xludf.DUMMYFUNCTION("""COMPUTED_VALUE"""),"003/003") -> 003/003 | W10: =IFERROR(__xludf.DUMMYFUNCTION("""COMPUTED_VALUE"""),"KEDUNG GEDE") -> KEDUNG GEDE | X10: =IFERROR(__xludf.DUMMYFUNCTION("""COMPUTED_VALUE"""),"BANYUMAS") -> BANYUMAS | Y10: =IFERROR(__xludf.DUMMYFUNCTION("""COMPUTED_VALUE"""),"KAB.BANYUMAS") -> KAB.BANYUMAS | Z10: =IFERROR(__xludf.DUMMYFUNCTION("""COMPUTED_VALUE"""),"JAWA TENGAH") -> JAWA TENGAH | AA10: =IFERROR(__xludf.DUMMYFUNCTION("""COMPUTED_VALUE"""),"53192") -> 53192 | AB10: =IFERROR(__xludf.DUMMYFUNCTION("""COMPUTED_VALUE"""),"3301061001950001") -> 3301061001950001 | AC10: =IFERROR(__xludf.DUMMYFUNCTION("""COMPUTED_VALUE"""),"92.983.066.9-521.000") -> 92.983.066.9-521.000 | AD10: =IFERROR(__xludf.DUMMYFUNCTION("""COMPUTED_VALUE"""),"CUM - KRS") -> CUM - KRS | AE10: =IFERROR(__xludf.DUMMYFUNCTION("""COMPUTED_VALUE"""),"SUB KARSINI") -> SUB KARSINI | AF10: =IFERROR(__xludf.DUMMYFUNCTION("""COMPUTED_VALUE"""),"081213283240") -> 081213283240 | AG10: =IFERROR(__xludf.DUMMYFUNCTION("""COMPUTED_VALUE"""),"081213283240") -> 081213283240 | AI10: =IFERROR(__xludf.DUMMYFUNCTION("""COMPUTED_VALUE"""),"53192S4") -> 53192S4 | AJ10: =IFERROR(__xludf.DUMMYFUNCTION("""COMPUTED_VALUE"""),"6210e241baa11a5eeb6f1193") -> 6210e241baa11a5eeb6f1193 | AK10: =IFERROR(__xludf.DUMMYFUNCTION("""COMPUTED_VALUE"""),"dm53192s4") -> dm53192s4 | AL10: =IFERROR(__xludf.DUMMYFUNCTION("""COMPUTED_VALUE"""),"password") -> password | AM10: =IFERROR(__xludf.DUMMYFUNCTION("""COMPUTED_VALUE"""),"KANTOR REGIONAL IV SEMARANG 50004") -> KANTOR REGIONAL IV SEMARANG 50004 | AN10: =IFERROR(__xludf.DUMMYFUNCTION("""COMPUTED_VALUE"""),"KPRK BANYUMAS 53100") -> KPRK BANYUMAS 53100 | AT10: =IFERROR(__xludf.DUMMYFUNCTION("""COMPUTED_VALUE"""),"-75,213,714.11") -> -75,213,714.11 | AU10: =IFERROR(__xludf.DUMMYFUNCTION("""COMPUTED_VALUE"""),"1,092,945,115") -> 1,092,945,115 | AV10: =IFERROR(__xludf.DUMMYFUNCTION("""COMPUTED_VALUE"""),"ADA") -> ADA | AW10: =IFERROR(__xludf.DUMMYFUNCTION("""COMPUTED_VALUE"""),"ADA") -> ADA | BA10: =IFERROR(__xludf.DUMMYFUNCTION("""COMPUTED_VALUE"""),"ADA") -> ADA | BB10: =IFERROR(__xludf.DUMMYFUNCTION("""COMPUTED_VALUE"""),"ADA") -> ADA | BE10: =IFERROR(__xludf.DUMMYFUNCTION("""COMPUTED_VALUE"""),"ADA") -> ADA | BF10: =IFERROR(__xludf.DUMMYFUNCTION("""COMPUTED_VALUE"""),"ADA") -> ADA | BG10: =IFERROR(__xludf.DUMMYFUNCTION("""COMPUTED_VALUE"""),"ADA") -> ADA | BL10: =IFERROR(__xludf.DUMMYFUNCTION("""COMPUTED_VALUE"""),"DEPOSIT") -> DEPOSIT | BV10: =IFERROR(__xludf.DUMMYFUNCTION("""COMPUTED_VALUE"""),"Perumahan New Grand Residence Blok O5, Kedung Gede Kec Banyumas Kab Banyumas Jawa Tengah") -> Perumahan New Grand Residence Blok O5, Kedung Gede Kec Banyumas Kab Banyumas Jawa Tengah
A11: =IFERROR(__xludf.DUMMYFUNCTION("""COMPUTED_VALUE"""),8.0) -> 8 | B11: =IFERROR(__xludf.DUMMYFUNCTION("""COMPUTED_VALUE"""),"11 Januari 2022") -> 11 Januari 2022 | C11: =IFERROR(__xludf.DUMMYFUNCTION("""COMPUTED_VALUE"""),"11 Januari 2022") -> 11 Januari 2022 | K11: =IFERROR(__xludf.DUMMYFUNCTION("""COMPUTED_VALUE"""),"PERANGKAT BELUM LENGKAP") -> PERANGKAT BELUM LENGKAP | P11: =IFERROR(__xludf.DUMMYFUNCTION("""COMPUTED_VALUE"""),"53BSPA23079BDGKT") -> 53BSPA23079BDGKT | Q11: =IFERROR(__xludf.DUMMYFUNCTION("""COMPUTED_VALUE"""),"KARTINI") -> KARTINI | R11: =IFERROR(__xludf.DUMMYFUNCTION("""COMPUTED_VALUE"""),"KARTINI") -> KARTINI | S11: =IFERROR(__xludf.DUMMYFUNCTION("""COMPUTED_VALUE"""),"Kartini") -> Kartini | T11: =IFERROR(__xludf.DUMMYFUNCTION("""COMPUTED_VALUE"""),"Nagrak Rt 02 Rw 07 Kel Jatisari Kec Cangkuang Kab Bandung Jawa Barat 40238") -> Nagrak Rt 02 Rw 07 Kel Jatisari Kec Cangkuang Kab Bandung Jawa Barat 40238 | U11: =IFERROR(__xludf.DUMMYFUNCTION("""COMPUTED_VALUE"""),"Nagrak RT 02 RW 07 Kel Jatisari Kec Cangkuang Kab Bandung Jawa Barat 40238") -> Nagrak RT 02 RW 07 Kel Jatisari Kec Cangkuang Kab Bandung Jawa Barat 40238 | V11: =IFERROR(__xludf.DUMMYFUNCTION("""COMPUTED_VALUE"""),"002/007") -> 002/007 | W11: =IFERROR(__xludf.DUMMYFUNCTION("""COMPUTED_VALUE"""),"JATISARI") -> JATISARI | X11: =IFERROR(__xludf.DUMMYFUNCTION("""COMPUTED_VALUE"""),"CANGKUANG") -> CANGKUANG | Y11: =IFERROR(__xludf.DUMMYFUNCTION("""COMPUTED_VALUE"""),"KAB. BANDUNG") -> KAB. BANDUNG | Z11: =IFERROR(__xludf.DUMMYFUNCTION("""COMPUTED_VALUE"""),"JAWA BARAT") -> JAWA BARAT | AA11: =IFERROR(__xludf.DUMMYFUNCTION("""COMPUTED_VALUE"""),"40238") -> 40238 | AB11: =IFERROR(__xludf.DUMMYFUNCTION("""COMPUTED_VALUE"""),"3204446104790006") -> 3204446104790006 | AC11: =IFERROR(__xludf.DUMMYFUNCTION("""COMPUTED_VALUE"""),"67.283.107.0-445.000") -> 67.283.107.0-445.000 | AD11: =IFERROR(__xludf.DUMMYFUNCTION("""COMPUTED_VALUE"""),"CUM - HDT") -> CUM - HDT | AE11: =IFERROR(__xludf.DUMMYFUNCTION("""COMPUTED_VALUE"""),"SUB HIDAYAT") -> SUB HIDAYAT | AF11: =IFERROR(__xludf.DUMMYFUNCTION("""COMPUTED_VALUE"""),"085723488915 / 085794803374") -> 085723488915 / 085794803374 | AG11: =IFERROR(__xludf.DUMMYFUNCTION("""COMPUTED_VALUE"""),"085723488915 / 085794803374") -> 085723488915 / 085794803374 | AH11: =IFERROR(__xludf.DUMMYFUNCTION("""COMPUTED_VALUE"""),"niekartini33@gmail.com") -> niekartini33@gmail.com | AI11: =IFERROR(__xludf.DUMMYFUNCTION("""COMPUTED_VALUE"""),"40361S4") -> 40361S4 | AJ11: =IFERROR(__xludf.DUMMYFUNCTION("""COMPUTED_VALUE"""),"620e1942a0e6bc1786602760") -> 620e1942a0e6bc1786602760 | AK11: =IFERROR(__xludf.DUMMYFUNCTION("""COMPUTED_VALUE"""),"dm40361s4") -> dm40361s4 | AL11: =IFERROR(__xludf.DUMMYFUNCTION("""COMPUTED_VALUE"""),"password") -> password | AM11: =IFERROR(__xludf.DUMMYFUNCTION("""COMPUTED_VALUE"""),"KANTOR REGIONAL III BANDUNG 40004") -> KANTOR REGIONAL III BANDUNG 40004 | AN11: =IFERROR(__xludf.DUMMYFUNCTION("""COMPUTED_VALUE"""),"KPRK SOREANG 40900") -> KPRK SOREANG 40900 | AO11: =IFERROR(__xludf.DUMMYFUNCTION("""COMPUTED_VALUE"""),"0408220022026") -> 0408220022026 | AP11: =IFERROR(__xludf.DUMMYFUNCTION("""COMPUTED_VALUE"""),"04082200220260001") -> 04082200220260001 | AT11: =IFERROR(__xludf.DUMMYFUNCTION("""COMPUTED_VALUE"""),"-7.0653866") -> -7.0653866 | AU11: =IFERROR(__xludf.DUMMYFUNCTION("""COMPUTED_VALUE"""),"1,075,471,922") -> 1,075,471,922 | AV11: =IFERROR(__xludf.DUMMYFUNCTION("""COMPUTED_VALUE"""),"BELUM ADA") -> BELUM ADA | AW11: =IFERROR(__xludf.DUMMYFUNCTION("""COMPUTED_VALUE"""),"ADA") -> ADA | BA11: =IFERROR(__xludf.DUMMYFUNCTION("""COMPUTED_VALUE"""),"ADA") -> ADA | BB11: =IFERROR(__xludf.DUMMYFUNCTION("""COMPUTED_VALUE"""),"ADA") -> ADA | BC11: =IFERROR(__xludf.DUMMYFUNCTION("""COMPUTED_VALUE"""),"ADA") -> ADA | BD11: =IFERROR(__xludf.DUMMYFUNCTION("""COMPUTED_VALUE"""),"ADA") -> ADA | BE11: =IFERROR(__xludf.DUMMYFUNCTION("""COMPUTED_VALUE"""),"ADA") -> ADA | BF11: =IFERROR(__xludf.DUMMYFUNCTION("""COMPUTED_VALUE"""),"ADA") -> ADA | BG11: =IFERROR(__xludf.DUMMYFUNCTION("""COMPUTED_VALUE"""),"ADA") -> ADA | BH11: =IFERROR(__xludf.DUMMYFUNCTION("""COMPUTED_VALUE"""),"TIDAK ADA") -> TIDAK ADA | BI11: =IFERROR(__xludf.DUMMYFUNCTION("""COMPUTED_VALUE"""),"ADA") -> ADA | BJ11: =IFERROR(__xludf.DUMMYFUNCTION("""COMPUTED_VALUE"""),"TIDAK ADA") -> TIDAK ADA | BK11: =IFERROR(__xludf.DUMMYFUNCTION("""COMPUTED_VALUE"""),"TIDAK ADA") -> TIDAK ADA | BL11: =IFERROR(__xludf.DUMMYFUNCTION("""COMPUTED_VALUE"""),"PLAFON") -> PLAFON | BV11: =IFERROR(__xludf.DUMMYFUNCTION("""COMPUTED_VALUE"""),"Nagrak Rt 02 Rw 07 Kel Jatisari Kec Cangkuang Kab Bandung Jawa Barat 40238") -> Nagrak Rt 02 Rw 07 Kel Jatisari Kec Cangkuang Kab Bandung Jawa Barat 40238
A12: =IFERROR(__xludf.DUMMYFUNCTION("""COMPUTED_VALUE"""),9.0) -> 9 | B12: =IFERROR(__xludf.DUMMYFUNCTION("""COMPUTED_VALUE"""),"12 Januari 2022") -> 12 Januari 2022 | C12: =IFERROR(__xludf.DUMMYFUNCTION("""COMPUTED_VALUE"""),"12 Januari 2022") -> 12 Januari 2022 | K12: =IFERROR(__xludf.DUMMYFUNCTION("""COMPUTED_VALUE"""),"PERANGKAT BELUM LENGKAP") -> PERANGKAT BELUM LENGKAP | P12: =IFERROR(__xludf.DUMMYFUNCTION("""COMPUTED_VALUE"""),"KH3SPA26075JBRHD") -> KH3SPA26075JBRHD | Q12: =IFERROR(__xludf.DUMMYFUNCTION("""COMPUTED_VALUE"""),"Berkah Putra ") -> Berkah Putra | R12: =IFERROR(__xludf.DUMMYFUNCTION("""COMPUTED_VALUE"""),"BERKAH PUTRA") -> BERKAH PUTRA | S12: =IFERROR(__xludf.DUMMYFUNCTION("""COMPUTED_VALUE"""),"Deden Susnandar") -> Deden Susnandar | T12: =IFERROR(__xludf.DUMMYFUNCTION("""COMPUTED_VALUE"""),"Kp Cipinang Rt 02 Rw 13 Kel Cipinang Kec Cimaung Kab Bandung Jawa Barat 40375") -> Kp Cipinang Rt 02 Rw 13 Kel Cipinang Kec Cimaung Kab Bandung Jawa Barat 40375 | U12: =IFERROR(__xludf.DUMMYFUNCTION("""COMPUTED_VALUE"""),"Kp Cipinang RT 02 RW 13 Kel Cipinang Kec Cimaung Kab Bandung Jawa Barat 40375") -> Kp Cipinang RT 02 RW 13 Kel Cipinang Kec Cimaung Kab Bandung Jawa Barat 40375 | V12: =IFERROR(__xludf.DUMMYFUNCTION("""COMPUTED_VALUE"""),"002/13") -> 002/13 | W12: =IFERROR(__xludf.DUMMYFUNCTION("""COMPUTED_VALUE"""),"CIPINANG") -> CIPINANG | X12: =IFERROR(__xludf.DUMMYFUNCTION("""COMPUTED_VALUE"""),"CIMAUNG") -> CIMAUNG | Y12: =IFERROR(__xludf.DUMMYFUNCTION("""COMPUTED_VALUE"""),"KAB. BANDUNG") -> KAB. BANDUNG | Z12: =IFERROR(__xludf.DUMMYFUNCTION("""COMPUTED_VALUE"""),"JAWA BARAT") -> JAWA BARAT | AA12: =IFERROR(__xludf.DUMMYFUNCTION("""COMPUTED_VALUE"""),"40375") -> 40375 | AB12: =IFERROR(__xludf.DUMMYFUNCTION("""COMPUTED_VALUE"""),"3204172103700001") -> 3204172103700001 | AC12: =IFERROR(__xludf.DUMMYFUNCTION("""COMPUTED_VALUE"""),"92.973.733.6-445.000") -> 92.973.733.6-445.000 | AD12: =IFERROR(__xludf.DUMMYFUNCTION("""COMPUTED_VALUE"""),"CUM - HDT") -> CUM - HDT | AE12: =IFERROR(__xludf.DUMMYFUNCTION("""COMPUTED_VALUE"""),"Sub Hidayat") -> Sub Hidayat | AF12: =IFERROR(__xludf.DUMMYFUNCTION("""COMPUTED_VALUE"""),"0813-2262-0525") -> 0813-2262-0525 | AG12: =IFERROR(__xludf.DUMMYFUNCTION("""COMPUTED_VALUE"""),"0813-2262-0525") -> 0813-2262-0525 | AH12: =IFERROR(__xludf.DUMMYFUNCTION("""COMPUTED_VALUE"""),"dsnandar65@gmail.com") -> dsnandar65@gmail.com | AI12: =IFERROR(__xludf.DUMMYFUNCTION("""COMPUTED_VALUE"""),"40374S4") -> 40374S4 | AJ12: =IFERROR(__xludf.DUMMYFUNCTION("""COMPUTED_VALUE"""),"6231b59a1c70080ee15d946a") -> 6231b59a1c70080ee15d946a | AK12: =IFERROR(__xludf.DUMMYFUNCTION("""COMPUTED_VALUE"""),"dm40374s4") -> dm40374s4 | AL12: =IFERROR(__xludf.DUMMYFUNCTION("""COMPUTED_VALUE"""),"password") -> password | AM12: =IFERROR(__xludf.DUMMYFUNCTION("""COMPUTED_VALUE"""),"KANTOR REGIONAL III BANDUNG 40004") -> KANTOR REGIONAL III BANDUNG 40004 | AN12: =IFERROR(__xludf.DUMMYFUNCTION("""COMPUTED_VALUE"""),"KPRK SOREANG 40900") -> KPRK SOREANG 40900 | AO12: =IFERROR(__xludf.DUMMYFUNCTION("""COMPUTED_VALUE"""),"0308220026461") -> 0308220026461 | AP12: =IFERROR(__xludf.DUMMYFUNCTION("""COMPUTED_VALUE"""),"03082200264610001") -> 03082200264610001 | AT12: =IFERROR(__xludf.DUMMYFUNCTION("""COMPUTED_VALUE"""),"-71,067,736") -> -71,067,736 | AU12: =IFERROR(__xludf.DUMMYFUNCTION("""COMPUTED_VALUE"""),"1,075,636,071") -> 1,075,636,071 | AV12: =IFERROR(__xludf.DUMMYFUNCTION("""COMPUTED_VALUE"""),"BELUM ADA") -> BELUM ADA | AW12: =IFERROR(__xludf.DUMMYFUNCTION("""COMPUTED_VALUE"""),"ADA") -> ADA | BA12: =IFERROR(__xludf.DUMMYFUNCTION("""COMPUTED_VALUE"""),"ADA") -> ADA | BB12: =IFERROR(__xludf.DUMMYFUNCTION("""COMPUTED_VALUE"""),"ADA") -> ADA | BC12: =IFERROR(__xludf.DUMMYFUNCTION("""COMPUTED_VALUE"""),"ADA") -> ADA | BD12: =IFERROR(__xludf.DUMMYFUNCTION("""COMPUTED_VALUE"""),"ADA") -> ADA | BE12: =IFERROR(__xludf.DUMMYFUNCTION("""COMPUTED_VALUE"""),"ADA") -> ADA | BF12: =IFERROR(__xludf.DUMMYFUNCTION("""COMPUTED_VALUE"""),"ADA") -> ADA | BG12: =IFERROR(__xludf.DUMMYFUNCTION("""COMPUTED_VALUE"""),"ADA") -> ADA | BH12: =IFERROR(__xludf.DUMMYFUNCTION("""COMPUTED_VALUE"""),"TIDAK ADA") -> TIDAK ADA | BI12: =IFERROR(__xludf.DUMMYFUNCTION("""COMPUTED_VALUE"""),"TIDAK ADA") -> TIDAK ADA | BJ12: =IFERROR(__xludf.DUMMYFUNCTION("""COMPUTED_VALUE"""),"TIDAK ADA") -> TIDAK ADA | BK12: =IFERROR(__xludf.DUMMYFUNCTION("""COMPUTED_VALUE"""),"TIDAK ADA") -> TIDAK ADA | BL12: =IFERROR(__xludf.DUMMYFUNCTION("""COMPUTED_VALUE"""),"PLAFON") -> PLAFON | BV12: =IFERROR(__xludf.DUMMYFUNCTION("""COMPUTED_VALUE"""),"Kp Cipinang Rt 02 Rw 13 Kel Cipinang Kec Cimaung Kab Bandung Jawa Barat 40375") -> Kp Cipinang Rt 02 Rw 13 Kel Cipinang Kec Cimaung Kab Bandung Jawa Barat 40375
A13: =IFERROR(__xludf.DUMMYFUNCTION("""COMPUTED_VALUE"""),10.0) -> 10 | B13: =IFERROR(__xludf.DUMMYFUNCTION("""COMPUTED_VALUE"""),"12 Januari 2022") -> 12 Januari 2022 | C13: =IFERROR(__xludf.DUMMYFUNCTION("""COMPUTED_VALUE"""),"12 Januari 2022") -> 12 Januari 2022 | K13: =IFERROR(__xludf.DUMMYFUNCTION("""COMPUTED_VALUE"""),"perangkat sudah lengkap, tidak ada petlok") -> perangkat sudah lengkap, tidak ada petlok | P13: =IFERROR(__xludf.DUMMYFUNCTION("""COMPUTED_VALUE"""),"52BSPA22071JTGKR") -> 52BSPA22071JTGKR | Q13: =IFERROR(__xludf.DUMMYFUNCTION("""COMPUTED_VALUE"""),"RIFDA") -> RIFDA | R13: =IFERROR(__xludf.DUMMYFUNCTION("""COMPUTED_VALUE"""),"RIFDA") -> RIFDA | S13: =IFERROR(__xludf.DUMMYFUNCTION("""COMPUTED_VALUE"""),"Rifky Anggara Mardhyatmoko") -> Rifky Anggara Mardhyatmoko | T13: =IFERROR(__xludf.DUMMYFUNCTION("""COMPUTED_VALUE"""),"Dukuh Kemantren Rt 02 Rw 01 ") -> Dukuh Kemantren Rt 02 Rw 01 | U13: =IFERROR(__xludf.DUMMYFUNCTION("""COMPUTED_VALUE"""),"DUKUH KEMANTREN RT 02 RW 01 DESA KRETEK, KECAMATAN ROWOKELE, 54472") -> DUKUH KEMANTREN RT 02 RW 01 DESA KRETEK, KECAMATAN ROWOKELE, 54472 | V13: =IFERROR(__xludf.DUMMYFUNCTION("""COMPUTED_VALUE"""),"002/001") -> 002/001 | W13: =IFERROR(__xludf.DUMMYFUNCTION("""COMPUTED_VALUE"""),"DS.KRETEK") -> DS.KRETEK | X13: =IFERROR(__xludf.DUMMYFUNCTION("""COMPUTED_VALUE"""),"KEC.ROWOKELE") -> KEC.ROWOKELE | Y13: =IFERROR(__xludf.DUMMYFUNCTION("""COMPUTED_VALUE"""),"KAB. KEBUMEN") -> KAB. KEBUMEN | Z13: =IFERROR(__xludf.DUMMYFUNCTION("""COMPUTED_VALUE"""),"JAWA TENGAH") -> JAWA TENGAH | AA13: =IFERROR(__xludf.DUMMYFUNCTION("""COMPUTED_VALUE"""),"54472") -> 54472 | AB13: =IFERROR(__xludf.DUMMYFUNCTION("""COMPUTED_VALUE"""),"3305170503910003") -> 3305170503910003 | AC13: =IFERROR(__xludf.DUMMYFUNCTION("""COMPUTED_VALUE"""),"71.741.044.3-523.000") -> 71.741.044.3-523.000 | AD13: =IFERROR(__xludf.DUMMYFUNCTION("""COMPUTED_VALUE"""),"CUM - KRS") -> CUM - KRS | AE13: =IFERROR(__xludf.DUMMYFUNCTION("""COMPUTED_VALUE"""),"SUB KARSINI") -> SUB KARSINI | AF13: =IFERROR(__xludf.DUMMYFUNCTION("""COMPUTED_VALUE"""),"081356333315") -> 081356333315 | AG13: =IFERROR(__xludf.DUMMYFUNCTION("""COMPUTED_VALUE"""),"081356333315") -> 081356333315 | AH13: =IFERROR(__xludf.DUMMYFUNCTION("""COMPUTED_VALUE"""),"angga.tisangga.tisna85@gmail.com") -> angga.tisangga.tisna85@gmail.com | AI13: =IFERROR(__xludf.DUMMYFUNCTION("""COMPUTED_VALUE"""),"54372S1") -> 54372S1 | AJ13: =IFERROR(__xludf.DUMMYFUNCTION("""COMPUTED_VALUE"""),"61f25fba1f8c4b129846a7f5") -> 61f25fba1f8c4b129846a7f5 | AK13: =IFERROR(__xludf.DUMMYFUNCTION("""COMPUTED_VALUE"""),"dm54372s1") -> dm54372s1 | AL13: =IFERROR(__xludf.DUMMYFUNCTION("""COMPUTED_VALUE"""),"password") -> password | AM13: =IFERROR(__xludf.DUMMYFUNCTION("""COMPUTED_VALUE"""),"KANTOR REGIONAL IV SEMARANG 50004") -> KANTOR REGIONAL IV SEMARANG 50004 | AN13: =IFERROR(__xludf.DUMMYFUNCTION("""COMPUTED_VALUE"""),"KPRK KEBUMEN 54300") -> KPRK KEBUMEN 54300 | AO13: =IFERROR(__xludf.DUMMYFUNCTION("""COMPUTED_VALUE"""),"0108220052388") -> 0108220052388 | AP13: =IFERROR(__xludf.DUMMYFUNCTION("""COMPUTED_VALUE"""),"01082200523880001") -> 01082200523880001 | AT13: =IFERROR(__xludf.DUMMYFUNCTION("""COMPUTED_VALUE"""),"7°36’01.2") -> 7°36’01.2 | AU13: =IFERROR(__xludf.DUMMYFUNCTION("""COMPUTED_VALUE"""),"109°27’33,1") -> 109°27’33,1 | AV13: =IFERROR(__xludf.DUMMYFUNCTION("""COMPUTED_VALUE"""),"ADA") -> ADA | AW13: =IFERROR(__xludf.DUMMYFUNCTION("""COMPUTED_VALUE"""),"ADA") -> ADA | BA13: =IFERROR(__xludf.DUMMYFUNCTION("""COMPUTED_VALUE"""),"ADA") -> ADA | BB13: =IFERROR(__xludf.DUMMYFUNCTION("""COMPUTED_VALUE"""),"ADA") -> ADA | BC13: =IFERROR(__xludf.DUMMYFUNCTION("""COMPUTED_VALUE"""),"ADA") -> ADA | BD13: =IFERROR(__xludf.DUMMYFUNCTION("""COMPUTED_VALUE"""),"ADA") -> ADA | BE13: =IFERROR(__xludf.DUMMYFUNCTION("""COMPUTED_VALUE"""),"ada") -> ada | BF13: =IFERROR(__xludf.DUMMYFUNCTION("""COMPUTED_VALUE"""),"ADA") -> ADA | BG13: =IFERROR(__xludf.DUMMYFUNCTION("""COMPUTED_VALUE"""),"ADA") -> ADA | BH13: =IFERROR(__xludf.DUMMYFUNCTION("""COMPUTED_VALUE"""),"EP-9200") -> EP-9200 | BI13: =IFERROR(__xludf.DUMMYFUNCTION("""COMPUTED_VALUE"""),"ADA") -> ADA | BJ13: =IFERROR(__xludf.DUMMYFUNCTION("""COMPUTED_VALUE"""),"ADA") -> ADA | BK13: =IFERROR(__xludf.DUMMYFUNCTION("""COMPUTED_VALUE"""),"TIDAK ADA") -> TIDAK ADA | BL13: =IFERROR(__xludf.DUMMYFUNCTION("""COMPUTED_VALUE"""),"DEPOSIT") -> DEPOSIT | BU13: =IFERROR(__xludf.DUMMYFUNCTION("""COMPUTED_VALUE"""),"petugas pos siap bantu, loket Rifda susah dihub") -> petugas pos siap bantu, loket Rifda susah dihub | BV13: =IFERROR(__xludf.DUMMYFUNCTION("""COMPUTED_VALUE"""),"Dukuh Kemantren Rt 02 Rw 01 ") -> Dukuh Kemantren Rt 02 Rw 01
A14: =IFERROR(__xludf.DUMMYFUNCTION("""COMPUTED_VALUE"""),11.0) -> 11 | B14: =IFERROR(__xludf.DUMMYFUNCTION("""COMPUTED_VALUE"""),"12 Januari 2022") -> 12 Januari 2022 | C14: =IFERROR(__xludf.DUMMYFUNCTION("""COMPUTED_VALUE"""),"12 Januari 2022") -> 12 Januari 2022 | F14: =IFERROR(__xludf.DUMMYFUNCTION("""COMPUTED_VALUE"""),"16 AGUSTUS 2022") -> 16 AGUSTUS 2022 | G14: =IFERROR(__xludf.DUMMYFUNCTION("""COMPUTED_VALUE"""),44789.0) -> 44789 | I14: =IFERROR(__xludf.DUMMYFUNCTION("""COMPUTED_VALUE"""),"16-08-22") -> 16-08-22 | J14: =IFERROR(__xludf.DUMMYFUNCTION("""COMPUTED_VALUE"""),"15-09-22") -> 15-09-22 | P14: =IFERROR(__xludf.DUMMYFUNCTION("""COMPUTED_VALUE"""),"KH2BSPA27003JBEN") -> KH2BSPA27003JBEN | Q14: =IFERROR(__xludf.DUMMYFUNCTION("""COMPUTED_VALUE"""),"pp ananda 01") -> pp ananda 01 | R14: =IFERROR(__xludf.DUMMYFUNCTION("""COMPUTED_VALUE"""),"PP ANANDA 01") -> PP ANANDA 01 | S14: =IFERROR(__xludf.DUMMYFUNCTION("""COMPUTED_VALUE"""),"Riyaddi Mulya") -> Riyaddi Mulya | T14: =IFERROR(__xludf.DUMMYFUNCTION("""COMPUTED_VALUE"""),"Jl.Nurkim No.09 Rt.03 Rw.12 ") -> Jl.Nurkim No.09 Rt.03 Rw.12 | U14: =IFERROR(__xludf.DUMMYFUNCTION("""COMPUTED_VALUE"""),"Jl.Nurkim No.09 RT.03 RW.12 Ds.KOTABATU KEC.CIOMAS ") -> Jl.Nurkim No.09 RT.03 RW.12 Ds.KOTABATU KEC.CIOMAS | V14: =IFERROR(__xludf.DUMMYFUNCTION("""COMPUTED_VALUE"""),"002/005") -> 002/005 | W14: =IFERROR(__xludf.DUMMYFUNCTION("""COMPUTED_VALUE"""),"DS.KOTA BATU") -> DS.KOTA BATU | X14: =IFERROR(__xludf.DUMMYFUNCTION("""COMPUTED_VALUE"""),"KEC.CIOMAS") -> KEC.CIOMAS | Y14: =IFERROR(__xludf.DUMMYFUNCTION("""COMPUTED_VALUE"""),"KAB. BOGOR") -> KAB. BOGOR | Z14: =IFERROR(__xludf.DUMMYFUNCTION("""COMPUTED_VALUE"""),"JAWA BARAT") -> JAWA BARAT | AA14: =IFERROR(__xludf.DUMMYFUNCTION("""COMPUTED_VALUE"""),"16610") -> 16610 | AB14: =IFERROR(__xludf.DUMMYFUNCTION("""COMPUTED_VALUE"""),"3201291307830006") -> 3201291307830006 | AC14: =IFERROR(__xludf.DUMMYFUNCTION("""COMPUTED_VALUE"""),"59.080.139.5.434.000") -> 59.080.139.5.434.000 | AD14: =IFERROR(__xludf.DUMMYFUNCTION("""COMPUTED_VALUE"""),"CUM - EEN") -> CUM - EEN | AE14: =IFERROR(__xludf.DUMMYFUNCTION("""COMPUTED_VALUE"""),"SUB KARSINI") -> SUB KARSINI | AF14: =IFERROR(__xludf.DUMMYFUNCTION("""COMPUTED_VALUE"""),"0852 1583 7717") -> 0852 1583 7717 | AG14: =IFERROR(__xludf.DUMMYFUNCTION("""COMPUTED_VALUE"""),"0852 1583 7717") -> 0852 1583 7717 | AH14: =IFERROR(__xludf.DUMMYFUNCTION("""COMPUTED_VALUE"""),"fauzi13andri@gmail.com") -> fauzi13andri@gmail.com | AI14: =IFERROR(__xludf.DUMMYFUNCTION("""COMPUTED_VALUE"""),"16618S1") -> 16618S1 | AJ14: =IFERROR(__xludf.DUMMYFUNCTION("""COMPUTED_VALUE"""),"620f2305ee26a37eab45889c") -> 620f2305ee26a37eab45889c | AK14: =IFERROR(__xludf.DUMMYFUNCTION("""COMPUTED_VALUE"""),"dm16618s1") -> dm16618s1 | AL14: =IFERROR(__xludf.DUMMYFUNCTION("""COMPUTED_VALUE"""),"password") -> password | AM14: =IFERROR(__xludf.DUMMYFUNCTION("""COMPUTED_VALUE"""),"KANTOR REGIONAL II JAKARTA 10004") -> KANTOR REGIONAL II JAKARTA 10004 | AN14: =IFERROR(__xludf.DUMMYFUNCTION("""COMPUTED_VALUE"""),"KPRK BOGOR 16000") -> KPRK BOGOR 16000 | AO14: =IFERROR(__xludf.DUMMYFUNCTION("""COMPUTED_VALUE"""),"0208220019585") -> 0208220019585 | AP14: =IFERROR(__xludf.DUMMYFUNCTION("""COMPUTED_VALUE"""),"02082200195850001") -> 02082200195850001 | AT14: =IFERROR(__xludf.DUMMYFUNCTION("""COMPUTED_VALUE"""),"-66,223") -> -66,223 | AU14: =IFERROR(__xludf.DUMMYFUNCTION("""COMPUTED_VALUE"""),"10,677,774") -> 10,677,774 | AV14: =IFERROR(__xludf.DUMMYFUNCTION("""COMPUTED_VALUE"""),"ADA") -> ADA | AW14: =IFERROR(__xludf.DUMMYFUNCTION("""COMPUTED_VALUE"""),"ADA") -> ADA | BA14: =IFERROR(__xludf.DUMMYFUNCTION("""COMPUTED_VALUE"""),"ADA") -> ADA | BB14: =IFERROR(__xludf.DUMMYFUNCTION("""COMPUTED_VALUE"""),"ADA") -> ADA | BC14: =IFERROR(__xludf.DUMMYFUNCTION("""COMPUTED_VALUE"""),"ADA") -> ADA | BD14: =IFERROR(__xludf.DUMMYFUNCTION("""COMPUTED_VALUE"""),"ADA") -> ADA | BE14: =IFERROR(__xludf.DUMMYFUNCTION("""COMPUTED_VALUE"""),"ADA") -> ADA | BF14: =IFERROR(__xludf.DUMMYFUNCTION("""COMPUTED_VALUE"""),"ADA") -> ADA | BG14: =IFERROR(__xludf.DUMMYFUNCTION("""COMPUTED_VALUE"""),"ADA") -> ADA | BI14: =IFERROR(__xludf.DUMMYFUNCTION("""COMPUTED_VALUE"""),"ADA") -> ADA | BJ14: =IFERROR(__xludf.DUMMYFUNCTION("""COMPUTED_VALUE"""),"ADA") -> ADA | BK14: =IFERROR(__xludf.DUMMYFUNCTION("""COMPUTED_VALUE"""),"ADA") -> ADA | BL14: =IFERROR(__xludf.DUMMYFUNCTION("""COMPUTED_VALUE"""),"PLAFON") -> PLAFON | BV14: =IFERROR(__xludf.DUMMYFUNCTION("""COMPUTED_VALUE"""),"Jl.Nurkim No.09 Rt.03 Rw.12 ") -> Jl.Nurkim No.09 Rt.03 Rw.12
